Workbook

Sheet Como preencher
A1: Como preencher
A2: 1. Colunas em AMARELO (L a O) são para preencher: links da Roma, Pneu Store e Achei Pneus, e o SKU da Achei.
A3: 2. Os 14 pneus já monitorados vieram preenchidos com os links atuais: use como exemplo do formato.
A4: 3. URL = endereço completo da página do produto, copiado do navegador (começa com https://).
A5: 4. SKU Achei = número do produto na Achei Pneus (o painel usa para ler preço e parcelas pela API).
A6: 5. Pneu que o concorrente não vende: deixe em branco e escreva "não vende" na Observação.
A7: 6. Produto diferente (outra medida ou desenho): cole o link e escreva "alternativo" na Observação.
A8: 7. Itens fora do site da Roma: o painel compara só os concorrentes até a Roma cadastrar o pneu.
A9: 8. Não mude os nomes das colunas: o painel vai ler este arquivo.

Sheet Resumo
A1: Resumo da base de itens
B3: Varejo | C3: Distribuição | D3: Total
A4: Itens na base | B4: =COUNTIFS(Itens!B2:B73,"Varejo") -> 59 | C4: =COUNTIFS(Itens!B2:B73,"Distribuição") -> 13 | D4: =COUNTIFS(Itens!A2:A73,">0") -> 72
A5: No site da Roma | B5: =COUNTIFS(Itens!B2:B73,"Varejo",Itens!I2:I73,"Sim") -> 53 | C5: =COUNTIFS(Itens!B2:B73,"Distribuição",Itens!I2:I73,"Sim") -> 3 | D5: =COUNTIFS(Itens!A2:A73,">0",Itens!I2:I73,"Sim") -> 56
A6: Fora do site da Roma | B6: =COUNTIFS(Itens!B2:B73,"Varejo",Itens!I2:I73,"Não") -> 6 | C6: =COUNTIFS(Itens!B2:B73,"Distribuição",Itens!I2:I73,"Não") -> 10 | D6: =COUNTIFS(Itens!A2:A73,">0",Itens!I2:I73,"Não") -> 16
A7: Já monitorados hoje | B7: =COUNTIFS(Itens!B2:B73,"Varejo",Itens!H2:H73,"Sim") -> 14 | C7: =COUNTIFS(Itens!B2:B73,"Distribuição",Itens!H2:H73,"Sim") -> 0 | D7: =COUNTIFS(Itens!A2:A73,">0",Itens!H2:H73,"Sim") -> 14
A8: Novos a monitorar | B8: =COUNTIFS(Itens!B2:B73,"Varejo",Itens!H2:H73,"Não") -> 45 | C8: =COUNTIFS(Itens!B2:B73,"Distribuição",Itens!H2:H73,"Não") -> 13 | D8: =COUNTIFS(Itens!A2:A73,">0",Itens!H2:H73,"Não") -> 58
A9: Pneus vendidos (mai–out) | B9: =SUMIFS(Itens!G2:G73,Itens!B2:B73,"Varejo") -> 9196 | C9: =SUMIFS(Itens!G2:G73,Itens!B2:B73,"Distribuição") -> 521 | D9: =SUM(Itens!G2:G73) -> 9717
A11: Links preenchidos | B11: Roma | C11: Pneu Store | D11: Achei Pneus
A12: Quantidade | B12: =COUNTA(Itens!L2:L73) -> 71 | C12: =COUNTA(Itens!M2:M73) -> 71 | D12: =COUNTA(Itens!N2:N73) -> 66
A14: Fonte: aba "TOP Vendas maio a Out" e aba "Pneus-SIte2" do arquivo Base_de_itens_para_o_site.xlsx, enviado pelo Lucas.

Sheet Itens
A1: ID | B1: Canal | C1: Posição no canal | D1: Produto (base de vendas) | E1: Medida | F1: Tipo | G1: Qtd vendida (mai–out) | H1: Já monitorado hoje? | I1: No site da Roma? | J1: Código Roma | K1: Preço no site (R$) | L1: URL Roma | M1: URL Pneu Store | N1: URL Achei Pneus | O1: SKU Achei Pneus | P1: Observação
A2: 1 | B2: Varejo | C2: 1 | D2: 175/65R14 KELLY EDGE TOURING 2 86H XL | E2: 175/65R14 | F2: Passeio | G2: 567 | H2: Sim | I2: Sim | J2: 924096 | K2: 306.81 | L2: https://romapneus.com.br/175-65-r14-edgetouring2 | M2: https://www.pneustore.com.br/pneu-kelly-by-goodyear-aro-14-edge-touring-2-175-65r14-86h-xl-16007686 | N2: https://www.acheipneus.com.br/pneu-17565r14-goodyear-kelly-edge-touring-2-86h | O2: 50564
A3: 2 | B3: Varejo | C3: 2 | D3: 175/65R14 ASSURANCE MAXLIFE 86H XL | E3: 175/65R14 | F3: Passeio | G3: 482 | H3: Sim | I3: Sim | J3: 923865 | K3: 353.31 | L3: https://romapneus.com.br/175-65-r14-maxlifeh2 | M3: https://www.pneustore.com.br/pneu-goodyear-aro-14-assurance-maxlife-175-65r14-86h-xl-10130199 | N3: https://www.acheipneus.com.br/pneu-175-65r14-goodyear-assurance-maxlife-86h-p994546 | O3: 26397
A4: 3 | B4: Varejo | C4: 3 | D4: 175/70R13 EDGE TOURING 2 82T SL | E4: 175/70R13 | F4: Passeio | G4: 433 | H4: Sim | I4: Sim | J4: 924049 | K4: 297.51 | L4: https://romapneus.com.br/175-70-r13-edgetouring2 | M4: https://www.pneustore.com.br/pneu-kelly-by-goodyear-aro-13-edge-touring-2-175-70r13-82t-16009113 | N4: https://www.acheipneus.com.br/pneu-17570r13-goodyear-kelly-edge-touring-2-82t | O4: 50705
A5: 4 | B5: Varejo | C5: 4 | D5: 205/55R17 WRANGLER TERRITORY HT 91V SL | E5: 205/55R17 | F5: SUV / Caminhonete | G5: 385 | H5: Não | I5: Sim | J5: 923986 | K5: 711.36 | L5: https://romapneus.com.br/205-55-r17-wranglerterritory | M5: https://www.pneustore.com.br/pneu-goodyear-aro-17-wrangler-territory-ht-205-55r17-91v-16004182 | N5: https://www.acheipneus.com.br/pneu-205-55r17-goodyear-wrangler-territory-ht-91v-p999658 | P5: Somadas 2 linhas da base (com e sem "F" no nome): mesmo código no site
A6: 5 | B6: Varejo | C6: 5 | D6: 205/55R16 EAGLE SPORT 2 91V SL | E6: 205/55R16 | F6: Passeio | G6: 309 | H6: Não | I6: Sim | J6: 111418 | K6: 446.31 | L6: https://romapneus.com.br/205-55-r16-eaglesport2 | M6: https://www.pneustore.com.br/pneu-goodyear-aro-16-eagle-sport-2-205-55r16-91v-16001418 | N6: https://www.acheipneus.com.br/pneu-205-55r16-goodyear-eagle-sport-2-91v-p998372
A7: 6 | B7: Varejo | C7: 6 | D7: 185/60R15 EDGE SPORT 2 88H XL | E7: 185/60R15 | F7: Passeio | G7: 275 | H7: Sim | I7: Sim | J7: 1452 | K7: 423.06 | L7: https://romapneus.com.br/185-60r15-edge-sport-2-88h-xl | M7: https://www.pneustore.com.br/pneu-kelly-by-goodyear-aro-15-edge-sport-2-185-60r15-88h-xl-16015387 | N7: https://www.acheipneus.com.br/pneu-18560r15-goodyear-kelly-edge-sport-2-88h | O7: 59684
A8: 7 | B8: Varejo | C8: 7 | D8: 205/65R16 EFFICIENTGRIP SUV 95H SL | E8: 205/65R16 | F8: SUV / Caminhonete | G8: 271 | H8: Sim | I8: Sim | J8: 923983 | K8: 619.29 | L8: https://romapneus.com.br/205-65-r16-efficientgripsuv2 | M8: https://www.pneustore.com.br/pneu-goodyear-aro-16-efficientgrip-suv-205-65r16-95h-16001154 | N8: https://www.acheipneus.com.br/pneu-205-65-r16-efficientgrip-suv-95h-goodyear-original-hyundai-creta-p988568 | O8: 2042
A9: 8 | B9: Varejo | C9: 8 | D9: 215/55R17 94V EFFIGRIP SUV SL | E9: 215/55R17 | F9: SUV / Caminhonete | G9: 254 | H9: Sim | I9: Sim | J9: 2081 | K9: 702.99 | L9: https://romapneus.com.br/215-55r17-94v-effigrip-suv-sl | M9: https://www.pneustore.com.br/pneu-goodyear-aro-17-efficientgrip-suv-215-55r17-94v-16017792 | N9: https://www.acheipneus.com.br/pneu-215-55r17-efficientgrip-suv-goodyear-94v-p989035 | O9: 20303
A10: 9 | B10: Varejo | C10: 9 | D10: 185/60R15 EAGLE SPORT 2 88H XL | E10: 185/60R15 | F10: Passeio | G10: 252 | H10: Não | I10: Sim | J10: 923976 | K10: 479.79 | L10: https://romapneus.com.br/185-60-r15-eaglesport2 | M10: https://www.pneustore.com.br/pneu-goodyear-aro-15-eagle-sport-2-185-60r15-88h-xl-16001785 | N10: https://www.acheipneus.com.br/pneu-185-60r15-goodyear-eagle-sport-2-88h-p999962
A11: 10 | B11: Varejo | C11: 10 | D11: 185/65R15 EAGLE SPORT 2 88H SL | E11: 185/65R15 | F11: Passeio | G11: 250 | H11: Não | I11: Sim | J11: 923978 | K11: 483.51 | L11: https://romapneus.com.br/185-65-r15-eaglesport2sl | M11: https://www.pneustore.com.br/pneu-goodyear-aro-15-eagle-sport-2-185-65r15-88h-16001786 | N11: https://www.acheipneus.com.br/pneu-185-65r15-goodyear-eagle-sport-2-88h-p999739
A12: 11 | B12: Varejo | C12: 11 | D12: 215/60R17 EFFICIENTGRIP SUV 96H SL | E12: 215/60R17 | F12: SUV / Caminhonete | G12: 243 | H12: Não | I12: Sim | J12: 923982 | K12: 785.76 | L12: https://romapneus.com.br/215-65-r17-efficientgripsuv2 | M12: https://www.pneustore.com.br/pneu-goodyear-aro-17-efficientgrip-suv-215-60r17-96h-16001153 | N12: https://www.acheipneus.com.br/pneu-215-60-r17-efficientgrip-suv-goodyear-96h-original-hyundai-creta-asx-p988413
A13: 12 | B13: Varejo | C13: 12 | D13: 175/70R14 ASSURANCE MAXLIFE 88T XL | E13: 175/70R14 | F13: Passeio | G13: 220 | H13: Não | I13: Sim | J13: 923866 | K13: 406.32 | L13: https://romapneus.com.br/175-70-r14-assurancemaxlife2 | M13: https://www.pneustore.com.br/pneu-goodyear-aro-14-assurance-maxlife-175-70r14-88t-xl-10130217 | N13: https://www.acheipneus.com.br/pneu-175-70r14-goodyear-assurance-maxlife-88t-p995143
A14: 13 | B14: Varejo | C14: 13 | D14: 195/55R16 EFFICIENTGRIP PERFORMANCE 91V XL | E14: 195/55R16 | F14: Passeio | G14: 220 | H14: Sim | I14: Sim | J14: 923993 | K14: 557.91 | L14: https://romapneus.com.br/195-55-r16-efficientgripperformance1 | M14: https://www.pneustore.com.br/pneu-goodyear-aro-16-efficientgrip-performance-195-55r16-91v-xl-16004185 | N14: https://www.acheipneus.com.br/pneu-195-55-r16-efficientgrip-performance-91v-goodyear-p988638 | O14: 5233
A15: 14 | B15: Varejo | C15: 14 | D15: 175/70R14 KELLY EDGE TOURING 2 88T XL | E15: 175/70R14 | F15: Passeio | G15: 213 | H15: Sim | I15: Sim | J15: 924051 | K15: 368.19 | L15: https://romapneus.com.br/175-70-r14-edgetouring2 | M15: https://www.pneustore.com.br/pneu-kelly-by-goodyear-aro-14-edge-touring-2-175-70r14-88t-xl-16009114 | N15: https://www.acheipneus.com.br/pneu-17570r14-goodyear-kelly-edge-touring-2-88t | O15: 50473
A16: 15 | B16: Varejo | C16: 15 | D16: 205/60R16 WRANGLER TERRITORY HT 92H SL | E16: 205/60R16 | F16: SUV / Caminhonete | G16: 210 | H16: Não | I16: Sim | J16: 924104 | K16: 637.89 | L16: https://romapneus.com.br/205-60-r16-territoryht2 | M16: https://www.pneustore.com.br/pneu-goodyear-aro-16-wrangler-territory-ht-205-60r16-92h-16010631 | N16: https://www.acheipneus.com.br/pneu-205-60r16-goodyear-wrangler-territory-ht-92h-p999662
A17: 16 | B17: Varejo | C17: 16 | D17: 185/65R15 EDGE SPORT 2 88H SL | E17: 185/65R15 | F17: Passeio | G17: 206 | H17: Sim | I17: Sim | J17: 1445 | K17: 433.29 | L17: https://romapneus.com.br/185-65r15-edge-sport-2-88h-sl | M17: https://www.pneustore.com.br/pneu-kelly-by-goodyear-aro-15-edge-sport-2-185-65r15-88h-16015386 | N17: https://www.acheipneus.com.br/pneu-18565r15-goodyear-kelly-edge-sport-2-88h | O17: 59686
A18: 17 | B18: Varejo | C18: 17 | D18: 205/55R16 EDGE SPORT 2 91V SL | E18: 205/55R16 | F18: Passeio | G18: 186 | H18: Sim | I18: Sim | J18: 924044 | K18: 427.71 | L18: https://romapneus.com.br/205-55-r16-edgesport2 | M18: https://www.pneustore.com.br/pneu-kelly-by-goodyear-aro-16-edge-sport-2-205-55r16-91v-16009120 | N18: https://www.acheipneus.com.br/pneu-20555r16-goodyear-kelly-edge-sport-2-91v | O18: 50568
A19: 18 | B19: Varejo | C19: 18 | D19: 165/70R13 EDGE TOURING 2 83T XL | E19: 165/70R13 | F19: Passeio | G19: 155 | H19: Não | I19: Sim | J19: 924050 | K19: 306.81 | L19: https://romapneus.com.br/165-75-r13-edgetouring2 | M19: https://www.pneustore.com.br/pneu-kelly-by-goodyear-aro-13-edge-touring-2-165-70r13-83t-xl-16009112 | N19: https://www.acheipneus.com.br/pneu-16570r13-goodyear-kelly-edge-touring-2-83t
A20: 19 | B20: Varejo | C20: 19 | D20: 185/60R15 EFFICIENTGRIP PERF 88H XL | E20: 185/60R15 | F20: Passeio | G20: 150 | H20: Não | I20: Sim | J20: 923811 | K20: 529.08 | L20: https://romapneus.com.br/185-60-r15-efficientgripperf2 | M20: https://www.pneustore.com.br/pneu-goodyear-aro-15-efficientgrip-performance-185-60r15-88h-xl-10130112 | N20: https://www.acheipneus.com.br/pneu-185-60r15-efficientgrip-performance-88h-goodyear-p988162
A21: 20 | B21: Varejo | C21: 20 | D21: 195/55R15 EDGE SPORT 2 85H SL | E21: 195/55R15 | F21: Passeio | G21: 149 | H21: Não | I21: Sim | J21: 924055 | K21: 433.29 | L21: https://romapneus.com.br/185-55-r15-edgesport2 | M21: https://www.pneustore.com.br/pneu-kelly-by-goodyear-aro-15-edge-sport-2-195-55r15-85h-16009118 | N21: https://www.acheipneus.com.br/pneu-19555r15-goodyear-kelly-edge-sport-2-85h
A22: 21 | B22: Varejo | C22: 21 | D22: 195/65R15 EAGLE SPORT 2 91V SL | E22: 195/65R15 | F22: Passeio | G22: 143 | H22: Não | I22: Sim | J22: 923981 | K22: 502.11 | L22: https://romapneus.com.br/195-65-r15-eaglesport2 | M22: https://www.pneustore.com.br/pneu-goodyear-aro-15-eagle-sport-2-195-65r15-91v-16001787 | N22: https://www.acheipneus.com.br/pneu-195-65r15-eagle-sport-2-91v-goodyear-p1000408
A23: 22 | B23: Varejo | C23: 22 | D23: 185/70R14 EDGE TOURING 2 88H SL | E23: 185/70R14 | F23: Passeio | G23: 140 | H23: Não | I23: Sim | J23: 924054 | K23: 423.99 | L23: https://romapneus.com.br/185-70-r14-edgetouring2 | M23: https://www.pneustore.com.br/pneu-kelly-by-goodyear-aro-14-edge-touring-2-185-70r14-88h-16009284 | N23: https://www.acheipneus.com.br/pneu-18570r14-goodyear-kelly-edge-touring-2-88h
A24: 23 | B24: Varejo | C24: 23 | D24: 195/65R15 EDGE SPORT 2 91V SL | E24: 195/65R15 | F24: Passeio | G24: 134 | H24: Sim | I24: Sim | J24: 1453 | K24: 463.05 | L24: https://romapneus.com.br/195-65r15-edge-sport-2-91v-sl | M24: https://www.pneustore.com.br/pneu-kelly-by-goodyear-aro-15-edge-sport-2-195-65r15-91v-16015388 | N24: https://www.acheipneus.com.br/pneu-19565r15-goodyearkelly-edge-sport-2-91v | O24: 59687
A25: 24 | B25: Varejo | C25: 24 | D25: 225/55R18 WRL FORTITUDE HT 98V SL | E25: 225/55R18 | F25: SUV / Caminhonete | G25: 133 | H25: Não | I25: Sim | J25: 924069 | K25: 764.37 | L25: https://romapneus.com.br/225-55-r18-fortitudeht2 | M25: https://www.pneustore.com.br/pneu-goodyear-aro-18-wrangler-fortitude-ht-225-55r18-98v-16018865 | N25: https://www.acheipneus.com.br/pneu-22555r18-goodyear-wrangler-fortitude-ht-98v
A26: 25 | B26: Varejo | C26: 25 | D26: 175/70R13 ASSURANCE MAXLIFE 82T SL | E26: 175/70R13 | F26: Passeio | G26: 131 | H26: Sim | I26: Sim | J26: 923864 | K26: 353.31 | L26: https://romapneus.com.br/175-70-r13-assurancemaxlife2 | M26: https://www.pneustore.com.br/pneu-goodyear-aro-13-assurance-maxlife-175-70r13-82t-10130198 | N26: https://www.acheipneus.com.br/pneu-175-70r13-goodyear-assurance-maxlife-82t-p994549 | O26: 26497
A27: 26 | B27: Varejo | C27: 26 | D27: 205/45R18 EAGLE TOURING 86V SL | E27: 205/45R18 | F27: Passeio | G27: 131 | H27: Não | I27: Sim | J27: 923906 | K27: 645.33 | L27: https://romapneus.com.br/205-45-r18-eagletouring2 | M27: https://www.pneustore.com.br/pneu-goodyear-aro-18-eagle-touring-205-45r18-86v-10130221 | N27: https://www.acheipneus.com.br/pneu-205-45r18-goodyear-eagle-touring-86v-p995395
A28: 27 | B28: Varejo | C28: 27 | D28: 195/55R15 EAGLE SPORT 2 85H SL | E28: 195/55R15 | F28: Passeio | G28: 125 | H28: Não | I28: Sim | J28: 923975 | K28: 474.21 | L28: https://romapneus.com.br/195-55-r15-eaglesport2 | M28: https://www.pneustore.com.br/pneu-goodyear-aro-15-eagle-sport-2-195-55r15-85h-16001419 | N28: https://www.acheipneus.com.br/pneu-195-55r15-goodyear-eagle-sport-2-85h-p998375
A29: 28 | B29: Varejo | C29: 28 | D29: 215/65R16 WRANGLER FORTITUDE HT 102H XL | E29: 215/65R16 | F29: SUV / Caminhonete | G29: 124 | H29: Não | I29: Sim | J29: 923909 | K29: 708.57 | L29: https://romapneus.com.br/215-65-r16-fortitudeht2 | M29: https://www.pneustore.com.br/pneu-goodyear-aro-16-wrangler-fortitude-ht-215-65r16-102h-xl-16000524 | N29: https://www.acheipneus.com.br/pneu-215-65-r16-goodyear-wrangler-fortitude-102h-p996138 | O29: https://www.acheipneus.com.br/pneu-215-65-r16-goodyear-wrangler-fortitude-102h-p996138
A30: 29 | B30: Varejo | C30: 29 | D30: 175/65R15 EDGE SPORT 2 84T SL | E30: 175/65R15 | F30: Passeio | G30: 121 | H30: Não | I30: Sim | J30: 924057 | K30: 435.15 | L30: https://romapneus.com.br/175-65-r15-edgesport2 | M30: https://www.pneustore.com.br/pneu-kelly-by-goodyear-aro-15-edge-sport-2-175-65r15-84t-16009126 | N30: https://www.acheipneus.com.br/pneu-17565r15-goodyear-kelly-edge-sport-2-84t | O30: https://www.acheipneus.com.br/pneu-17565r15-goodyear-kelly-edge-sport-2-84t
A31: 30 | B31: Varejo | C31: 30 | D31: 215/50R17 EFFIGRIP PERF 91V HO | E31: 215/50R17 | F31: Passeio | G31: 111 | H31: Não | I31: Não | L31: https://romapneus.com.br/215-50r17-effigrip-perf-91v-ho | M31: https://www.pneustore.com.br/pneu-goodyear-aro-17-efficientgrip-performance-215-50r17-91v-16007242 | N31: https://www.acheipneus.com.br/pneu-215-50-r17-efficientgrip-performance-goodyear-91v-original-honda-civic-p988315 | O31: https://www.acheipneus.com.br/pneu-215-50-r17-efficientgrip-performance-goodyear-91v-original-honda-civic-p988315 | P31: Não está no site da Roma
A32: 31 | B32: Varejo | C32: 31 | D32: 225/60R18 WRL FORTITUDE HT 104H XL | E32: 225/60R18 | F32: SUV / Caminhonete | G32: 111 | H32: Não | I32: Sim | J32: 924068 | K32: 972.69 | L32: https://romapneus.com.br/225-65-r18-fortitudeht2 | M32: https://www.pneustore.com.br/pneu-goodyear-aro-18-wrangler-fortitude-ht-225-60r18-104h-xl-16009132 | N32: https://www.acheipneus.com.br/pneu-22560r18-goodyear-wrangler-fortitude-ht-104h | O32: https://www.acheipneus.com.br/pneu-22560r18-goodyear-wrangler-fortitude-ht-104h
A33: 32 | B33: Varejo | C33: 32 | D33: 205/60R15 EFFICIENTGRIP PERFORM 91H | E33: 205/60R15 | F33: Passeio | G33: 111 | H33: Não | I33: Sim | J33: 924079 | K33: 557.91 | L33: https://romapneus.com.br/185-60-r15-efficientgrip2 | M33: https://www.pneustore.com.br/pneu-goodyear-aro-15-efficientgrip-performance-205-60r15-91h-16037538 | N33: https://www.acheipneus.com.br/pneu-205-60-r15-efficientgrip-performance-goodyear-91h-crossfox-saveiro-cross-p988280
A34: 33 | B34: Varejo | C34: 33 | D34: 225/55R18 EFFICIENTGRIP SUV 98V SL | E34: 225/55R18 | F34: SUV / Caminhonete | G34: 108 | H34: Não | I34: Sim | J34: 923862 | K34: 841.56 | L34: https://romapneus.com.br/225-55-r18-efficientgripsuv2 | M34: https://www.pneustore.com.br/pneu-goodyear-aro-18-efficientgrip-suv-225-55r18-98v-10130193 | N34: https://www.acheipneus.com.br/pneu-225-55r18-efficientgrip-suv-98h-goodyear-ix35-p987742
A35: 34 | B35: Varejo | C35: 34 | D35: 185/55R16 EAGLE SPORT 2 83V SL | E35: 185/55R16 | F35: Passeio | G35: 103 | H35: Não | I35: Sim | J35: 923980 | K35: 618.36 | L35: https://romapneus.com.br/185-55-r16-eaglesport1 | M35: https://www.pneustore.com.br/pneu-goodyear-aro-16-eagle-sport-2-185-55r16-83v-16001789 | N35: https://www.acheipneus.com.br/pneu-185-55r16-goodyear-eagle-sport-2-83v-p1000550
A36: 35 | B36: Varejo | C36: 35 | D36: 185/65R15 EAGLE TOURING 88H SL DS BC70 | E36: 185/65R15 | F36: Passeio | G36: 102 | H36: Não | I36: Sim | J36: 924075 | K36: 763.52 | L36: https://romapneus.com.br/185-65-r15-eagletouring2 | M36: https://www.pneustore.com.br/pneu-goodyear-aro-15-eagle-touring-185-65r15-88h-16015122 | N36: https://www.acheipneus.com.br/pneu-185-65r15-goodyear-eagle-touring-88h-p1001150 | P36: Base diz "DS BC70"; no site está como "EAGLE TOURING SL": confirmar se é o mesmo
A37: 36 | B37: Varejo | C37: 36 | D37: 195/55R15 EFFICIENTGRIP PERF 85H SL | E37: 195/55R15 | F37: Passeio | G37: 101 | H37: Não | I37: Sim | J37: 923804 | K37: 549.54 | L37: https://romapneus.com.br/185-55-r15-efficientgripperf2 | M37: https://www.pneustore.com.br/pneu-goodyear-aro-15-efficientgrip-performance-195-55r15-85h-10130137 | N37: https://www.acheipneus.com.br/pneu-195-55-r15-efficientgrip-performance-85h-goodyear-original-fox-polo-p988163 | O37: https://www.acheipneus.com.br/pneu-195-55-r15-efficientgrip-performance-85h-goodyear-original-fox-polo-p988163
A38: 37 | B38: Varejo | C38: 37 | D38: 235/45R19 WRANGLER TERRITORY VW 95V SL | E38: 235/45R19 | F38: SUV / Caminhonete | G38: 100 | H38: Não | I38: Não | L38: https://romapneus.com.br/235-45r19-wrangler-territory-vw-95v-sl | M38: https://www.pneustore.com.br/pneu-goodyear-aro-19-wrangler-territory-ht-235-45r19-95v-16001417 | N38: https://www.acheipneus.com.br/pneu-235-45r19-goodyear-wrangler-territory-95v-p1000635 | P38: Não está no site da Roma
A39: 38 | B39: Varejo | C39: 38 | D39: 195/65R15 EFFICIENTGRIP PERFORMANCE 91H SL FP | E39: 195/65R15 | F39: Passeio | G39: 100 | H39: Não | I39: Sim | J39: 923926 | K39: 548.61 | L39: https://romapneus.com.br/195-65-r15-performancesl2 | M39: https://www.pneustore.com.br/pneu-goodyear-aro-15-efficientgrip-performance-195-65r15-91h-10130127 | N39: https://www.acheipneus.com.br/pneu-195-65-r15-efficientgrip-performance-91h-goodyear-p988165
A40: 39 | B40: Varejo | C40: 39 | D40: 205/50R17 EAGLE TOURING 89V SL | E40: 205/50R17 | F40: Passeio | G40: 98 | H40: Não | I40: Sim | J40: 923908 | K40: 776.46 | L40: https://romapneus.com.br/205-55-r17-eagletouring2 | M40: https://www.pneustore.com.br/pneu-goodyear-aro-17-eagle-touring-205-50r17-89v-10130215 | N40: https://www.acheipneus.com.br/pneu-205-50r17-goodyear-eagle-touring-89v-p995081
...
